<?xml version="1.0" encoding="utf-8"?>
<!-- This URDF was automatically created by SolidWorks to URDF Exporter! Originally created by Stephen Brawner (brawner@gmail.com) 
     Commit Version: 1.6.0-4-g7f85cfe  Build Version: 1.6.7995.38578
     For more information, please see http://wiki.ros.org/sw_urdf_exporter -->
<robot name="P4_right_arm">
  <link
    name="link_wy">
    <inertial>
      <origin
        xyz="-0.014687 -0.0021023 0.23867"
        rpy="0 0 0" />
      <mass
        value="15.389" />
      <inertia
        ixx="0.18177"
        ixy="0.00024076"
        ixz="-0.0034339"
        iyy="0.14251"
        iyz="0.00078292"
        izz="0.093304" />
    </inertial>
    <visual>
      <origin
        xyz="0 0 0"
        rpy="0 0 0" />
      <geometry>
        <mesh
          filename="../meshes/link_wy.STL" />
      </geometry>
      <material
        name="">
        <color
          rgba="0.75294 0.75294 0.75294 1" />
      </material>
    </visual>
    <collision>
      <origin
        xyz="0 0 0"
        rpy="0 0 0" />
      <geometry>
        <mesh
          filename="../meshes/link_wy.STL" />
      </geometry>
    </collision>
  </link>


  <joint
    name="joint_ra1"
    type="revolute">
    <origin
      xyz="-0.0079 -0.199 0.347"
      rpy="0 0 0" />
    <parent
      link="link_wy" />
    <child
      link="link_ra1" />
    <axis
      xyz="0 1 0" />
    <limit
      lower="-2.7576"
      upper="2.7576"
      effort="0"
      velocity="0" />
  </joint>


  <link
    name="link_ra1">
    <inertial>
      <origin
        xyz="0.0077276 0.0043398 -8.977E-05"
        rpy="0 0 0" />
      <mass
        value="1.1622" />
      <inertia
        ixx="0.0012266"
        ixy="-3.509E-05"
        ixz="1.539E-05"
        iyy="0.0013421"
        iyz="-1.643E-05"
        izz="0.0014863" />
    </inertial>
    <visual>
      <origin
        xyz="0 0 0"
        rpy="0 0 0" />
      <geometry>
        <mesh
          filename="../meshes/link_ra1.STL" />
      </geometry>
      <material
        name="">
        <color
          rgba="0.75294 0.75294 0.75294 1" />
      </material>
    </visual>
    <collision>
      <origin
        xyz="0 0 0"
        rpy="0 0 0" />
      <geometry>
        <mesh
          filename="../meshes/link_ra1.STL" />
      </geometry>
    </collision>
  </link>


  <joint
    name="joint_ra2"
    type="revolute">
    <origin
      xyz="0 0 0"
      rpy="0 0 0" />
    <parent
      link="link_ra1" />
    <child
      link="link_ra2" />
    <axis
      xyz="1 0 0" />
    <limit
      lower="-2.5656"
      upper="0.2618"
      effort="0"
      velocity="0" />
  </joint>

  <link
    name="link_ra2">
    <inertial>
      <origin
        xyz="0.00092472 -0.00010647 -0.091417"
        rpy="0 0 0" />
      <mass
        value="0.90448" />
      <inertia
        ixx="0.0014013"
        ixy="2.6E-06"
        ixz="7.97E-05"
        iyy="0.0016447"
        iyz="-2.64E-06"
        izz="0.00097982" />
    </inertial>
    <visual>
      <origin
        xyz="0 0 0"
        rpy="0 0 0" />
      <geometry>
        <mesh
          filename="../meshes/link_ra2.STL" />
      </geometry>
      <material
        name="">
        <color
          rgba="0.75294 0.75294 0.75294 1" />
      </material>
    </visual>
    <collision>
      <origin
        xyz="0 0 0"
        rpy="0 0 0" />
      <geometry>
        <mesh
          filename="../meshes/link_ra2.STL" />
      </geometry>
    </collision>
  </link>

  <joint
    name="joint_ra3"
    type="revolute">
    <origin
      xyz="-0.00025 0 0"
      rpy="0 0 0" />
    <parent
      link="link_ra2" />
    <child
      link="link_ra3" />
    <axis
      xyz="0 0 1" />
    <limit
      lower="-2.6354"
      upper="2.6354"
      effort="0"
      velocity="0" />
  </joint>

  <link
    name="link_ra3">
    <inertial>
      <origin
        xyz="0.0086139 -0.0022118 -0.23173"
        rpy="0 0 0" />
      <mass
        value="0.93017" />
      <inertia
        ixx="0.0027288"
        ixy="2.631E-05"
        ixz="-0.00022999"
        iyy="0.0026416"
        iyz="1.636E-05"
        izz="0.00073464" />
    </inertial>
    <visual>
      <origin
        xyz="0 0 0"
        rpy="0 0 0" />
      <geometry>
        <mesh
          filename="../meshes/link_ra3.STL" />
      </geometry>
      <material
        name="">
        <color
          rgba="0.89804 0.91765 0.92941 1" />
      </material>
    </visual>
    <collision>
      <origin
        xyz="0 0 0"
        rpy="0 0 0" />
      <geometry>
        <mesh
          filename="../meshes/link_ra3.STL" />
      </geometry>
    </collision>
  </link>

  <joint
    name="joint_ra4"
    type="revolute">
    <origin
      xyz="0 0 -0.2595"
      rpy="0 0 0" />
    <parent
      link="link_ra3" />
    <child
      link="link_ra4" />
    <axis
      xyz="1 0 0" />
    <limit
      lower="-0.2443"
      upper="2.2166"
      effort="0"
      velocity="0" />
  </joint>

  <link
    name="link_ra4">
    <inertial>
      <origin
        xyz="0.0088434 3.716E-05 -0.023669"
        rpy="0 0 0" />
      <mass
        value="0.16009" />
      <inertia
        ixx="0.00013057"
        ixy="1.4E-07"
        ixz="3.901E-05"
        iyy="0.00022049"
        iyz="-2.1E-07"
        izz="0.0001893" />
    </inertial>
    <visual>
      <origin
        xyz="0 0 0"
        rpy="0 0 0" />
      <geometry>
        <mesh
          filename="../meshes/link_ra4.STL" />
      </geometry>
      <material
        name="">
        <color
          rgba="0.89804 0.91765 0.92941 1" />
      </material>
    </visual>
    <collision>
      <origin
        xyz="0 0 0"
        rpy="0 0 0" />
      <geometry>
        <mesh
          filename="../meshes/link_ra4.STL" />
      </geometry>
    </collision>
  </link>

  <joint
    name="joint_ra5"
    type="revolute">
    <origin
      xyz="0 0 -0.0501"
      rpy="0 0 0" />
    <parent
      link="link_ra4" />
    <child
      link="link_ra5" />
    <axis
      xyz="0 0 1" />
    <limit
      lower="-2.9147"
      upper="2.9147"
      effort="0"
      velocity="0" />
  </joint>

  <link
    name="link_ra5">
    <inertial>
      <origin
        xyz="-0.00047941 0.00082489 -0.095559"
        rpy="0 0 0" />
      <mass
        value="1.8234" />
      <inertia
        ixx="0.010214"
        ixy="-2.47E-06"
        ixz="3.595E-05"
        iyy="0.01034"
        iyz="0.00011342"
        izz="0.0014763" />
    </inertial>
    <visual>
      <origin
        xyz="0 0 0"
        rpy="0 0 0" />
      <geometry>
        <mesh
          filename="../meshes/link_ra5.STL" />
      </geometry>
      <material
        name="">
        <color
          rgba="0.75294 0.75294 0.75294 1" />
      </material>
    </visual>
    <collision>
      <origin
        xyz="0 0 0"
        rpy="0 0 0" />
      <geometry>
        <mesh
          filename="../meshes/link_ra5.STL" />
      </geometry>
    </collision>
  </link>

  <joint
    name="joint_ra6"
    type="revolute">
    <origin
      xyz="0 -0.024 -0.2489"
      rpy="0 0 0" />
    <parent
      link="link_ra5" />
    <child
      link="link_ra6" />
    <axis
      xyz="1 0 0" />
    <limit
      lower="-0.9948"
      upper="0.9948"
      effort="0"
      velocity="0" />
  </joint>

  <link
    name="link_ra6">
    <inertial>
      <origin
        xyz="0 0.017559 0.00015073"
        rpy="0 0 0" />
      <mass
        value="0.021475" />
      <inertia
        ixx="3.14E-06"
        ixy="0"
        ixz="0"
        iyy="8.1E-07"
        iyz="2E-08"
        izz="3.33E-06" />
    </inertial>
    <visual>
      <origin
        xyz="0 0 0"
        rpy="0 0 0" />
      <geometry>
        <mesh
          filename="../meshes/link_ra6.STL" />
      </geometry>
      <material
        name="">
        <color
          rgba="0.75294 0.75294 0.75294 1" />
      </material>
    </visual>
    <collision>
      <origin
        xyz="0 0 0"
        rpy="0 0 0" />
      <geometry>
        <mesh
          filename="../meshes/link_ra6.STL" />
      </geometry>
    </collision>
  </link>

  <joint
    name="joint_ra7"
    type="revolute">
    <origin
      xyz="0 0 0"
      rpy="0 0 0" />
    <parent
      link="link_ra6" />
    <child
      link="link_ra7" />
    <axis
      xyz="0 1 0" />
    <limit
      lower="-0.4538"
      upper="0.4538"
      effort="0"
      velocity="0" />
  </joint>

  <link
    name="link_ra7">
    <inertial>
      <origin
        xyz="0.0058056 0.02443 -0.09525"
        rpy="0 0 0" />
      <mass
        value="0.55629" />
      <inertia
        ixx="0.0011834"
        ixy="0.00013486"
        ixz="2.361E-05"
        iyy="0.0015286"
        iyz="5.62E-05"
        izz="0.00057415" />
    </inertial>
    <visual>
      <origin
        xyz="0 0 0"
        rpy="0 0 0" />
      <geometry>
        <mesh
          filename="../meshes/link_ra7.STL" />
      </geometry>
      <material
        name="">
        <color
          rgba="0.75294 0.75294 0.75294 1" />
      </material>
    </visual>
    <collision>
      <origin
        xyz="0 0 0"
        rpy="0 0 0" />
      <geometry>
        <mesh
          filename="../meshes/link_ra7.STL" />
      </geometry>
    </collision>
  </link>
  <!--  添加工具可以在下面改
  <joint name="joint_changer" type="fixed">
    <origin xyz="0 0 -0.1055" rpy="0 0 0" />
    <parent link="link_ra7" />
    <child link="link_changer" />
    <axis xyz="0 0 0" />
  </joint>

  <link name="link_changer">
    <inertial>
      <origin xyz="0.0284177462155677 3.84545121056706E-05 -0.0589744027451906" rpy="0 0 0" />
      <mass value="0.653701734720013" />
      <inertia ixx="0.000526804921518331" ixy="-8.31383965323109E-08" ixz="1.79592188825725E-05" iyy="0.000523650820622731" iyz="3.78315492596218E-07" izz="0.000214811849928591" />
    </inertial>
    <visual>
      <origin xyz="0 0 0" rpy="0 0 0" />
      <geometry>
        <mesh filename="../meshes/meshes_arm_p3bib_r/link_changer.STL" />
      </geometry>
      <material name="">
        <color rgba="1 1 1 1" />
      </material>
    </visual>
    <collision>
      <origin xyz="0 0 0" rpy="0 0 0" />
      <geometry>
        <mesh filename="../meshes/meshes_arm_p3bib_r/link_changer.STL" />
      </geometry>
    </collision>
  </link>

  <joint name="joint_vacuum" type="fixed">
    <origin xyz="0.0375 0 -0.1185" rpy="0 0 0" />
    <parent link="link_changer" />
    <child link="link_vacuum" />
    <axis xyz="0 0 0" />
  </joint>

  <link name="link_vacuum">
  </link>
  -->
</robot>